Workbook

Sheet Executive Summary
B2: Food & Sales Budget Variance - Executive Summary
B3: August 2026 | Year-to-Date (Jan-Aug) | All Stores: Mesa 0008 / Polo 0025 / Woodridge 0028 / Dilley 0062
B5: =C15 -> 5502817.3 | D5: =E15 -> 0.7448318 | F5: =C15-D15 -> -1885182.7 | H5: =AVERAGE(I11:I14) -> 0.524225 | J5: =AVERAGE(J11:J14) -> 7.9320417
B8: YTD SALES (ACTUAL) | D8: BUDGET ATTAINMENT | F8: VARIANCE vs BUDGET | H8: AVG KITCHEN INIR MARGIN | J8: AVG SOS (KITCHEN)
B10: Store | C10: YTD Actual | D10: YTD Budget | E10: Attain % | F10: C-Store | G10: Kitchen | H10: Fountain | I10: INIR % | J10: SOS
B11: Mesa 0008 | C11: =SUM('0008'!J20:J27)+SUM('0008'!Q20:Q27) -> 1359367.8 | D11: =SUM('0008'!I20:I27)+SUM('0008'!P20:P27) -> 1688000 | E11: =C11/D11 -> 0.80531267 | F11: =SUM('0008'!D20:D27) -> 1133442 | G11: =SUM('0008'!G20:G27) -> 200604.77 | H11: =SUM('0008'!Q20:Q27) -> 25321.01 | I11: ='0008'!P13 -> 0.5733 | J11: ='0008'!S13 -> 7.3823333
B12: Polo 0025 | C12: =SUM('0025'!J20:J27)+SUM('0025'!Q20:Q27) -> 945994.04 | D12: =SUM('0025'!I20:I27)+SUM('0025'!P20:P27) -> 1868000 | E12: =C12/D12 -> 0.50642079 | F12: =SUM('0025'!D20:D27) -> 727083 | G12: =SUM('0025'!G20:G27) -> 193267.17 | H12: =SUM('0025'!Q20:Q27) -> 25643.87 | I12: ='0025'!P13 -> 0.4824 | J12: ='0025'!S13 -> 9.001
B13: Woodridge 0028 | C13: =SUM('0028'!J20:J27)+SUM('0028'!Q20:Q27) -> 1512530.2 | D13: =SUM('0028'!I20:I27)+SUM('0028'!P20:P27) -> 1864000 | E13: =C13/D13 -> 0.81144323 | F13: =SUM('0028'!D20:D27) -> 1265636 | G13: =SUM('0028'!G20:G27) -> 198388.13 | H13: =SUM('0028'!Q20:Q27) -> 48506.06 | I13: ='0028'!P13 -> 0.5377 | J13: ='0028'!S13 -> 5.4971667
B14: Dilley 0062 | C14: =SUM('0062'!J20:J27)+SUM('0062'!Q20:Q27) -> 1684925.3 | D14: =SUM('0062'!I20:I27)+SUM('0062'!P20:P27) -> 1968000 | E14: =C14/D14 -> 0.85616123 | F14: =SUM('0062'!D20:D27) -> 1334861 | G14: =SUM('0062'!G20:G27) -> 288502.77 | H14: =SUM('0062'!Q20:Q27) -> 61561.53 | I14: ='0062'!P13 -> 0.5035 | J14: ='0062'!S13 -> 9.8476667
B15: ALL STORES | C15: =SUM(C11:C14) -> 5502817.3 | D15: =SUM(D11:D14) -> 7388000 | E15: =C15/D15 -> 0.7448318 | F15: =SUM(F11:F14) -> 4461022 | G15: =SUM(G11:G14) -> 880762.84 | H15: =SUM(H11:H14) -> 161032.47 | I15: =AVERAGE(I11:I14) -> 0.524225 | J15: =AVERAGE(J11:J14) -> 7.9320417
B41: C-Store | C41: =SUM(F11:F14) -> 4461022
B42: Kitchen | C42: =SUM(G11:G14) -> 880762.84
B43: Fountain | C43: =SUM(H11:H14) -> 161032.47
B45: Hot Grab | C45: =SUM('0008'!C50:C57)+SUM('0025'!C50:C57)+SUM('0028'!C51:C58)+SUM('0062'!C51:C58) -> 339287.38
B46: Cold Grab | C46: =SUM('0008'!D50:D57)+SUM('0025'!D50:D57)+SUM('0028'!D51:D58)+SUM('0062'!D51:D58) -> 40294.19
B47: Bakery | C47: =SUM('0008'!E50:E57)+SUM('0025'!E50:E57)+SUM('0028'!E51:E58)+SUM('0062'!E51:E58) -> 13786.67
B48: MTO Food | C48: =SUM('0008'!F50:F57)+SUM('0025'!F50:F57)+SUM('0028'!F51:F58)+SUM('0062'!F51:F58) -> 345129.08
B49: MTO Coffee & Bev | C49: =SUM('0008'!G50:G57)+SUM('0025'!G50:G57)+SUM('0028'!G51:G58)+SUM('0062'!G51:G58) -> 47476.34
B50: Delivery | C50: =SUM('0008'!H50:H57)+SUM('0025'!H50:H57)+SUM('0028'!H51:H58)+SUM('0062'!H51:H58) -> 89043.63
B51: Catering | C51: =SUM('0008'!I50:I57)+SUM('0025'!I50:I57)+SUM('0028'!I51:I58)+SUM('0062'!I51:I58) -> 3667.64
B52: Midax | C52: =SUM('0008'!J50:J57)+SUM('0025'!J50:J57)+SUM('0028'!J51:J58)+SUM('0062'!J51:J58) -> 2119.04
B54: Month | C54: Actual | D54: Budget
B55: Jan | C55: ='0008'!J20+'0025'!J20+'0028'!J20+'0062'!J20+'0008'!Q20+'0025'!Q20+'0028'!Q20+'0062'!Q20 -> 577581.99 | D55: ='0008'!I20+'0025'!I20+'0028'!I20+'0062'!I20+'0008'!P20+'0025'!P20+'0028'!P20+'0062'!P20 -> 923500
B56: Feb | C56: ='0008'!J21+'0025'!J21+'0028'!J21+'0062'!J21+'0008'!Q21+'0025'!Q21+'0028'!Q21+'0062'!Q21 -> 588697.99 | D56: ='0008'!I21+'0025'!I21+'0028'!I21+'0062'!I21+'0008'!P21+'0025'!P21+'0028'!P21+'0062'!P21 -> 923500
B57: Mar | C57: ='0008'!J22+'0025'!J22+'0028'!J22+'0062'!J22+'0008'!Q22+'0025'!Q22+'0028'!Q22+'0062'!Q22 -> 695368.71 | D57: ='0008'!I22+'0025'!I22+'0028'!I22+'0062'!I22+'0008'!P22+'0025'!P22+'0028'!P22+'0062'!P22 -> 923500
B58: Apr | C58: ='0008'!J23+'0025'!J23+'0028'!J23+'0062'!J23+'0008'!Q23+'0025'!Q23+'0028'!Q23+'0062'!Q23 -> 669736.88 | D58: ='0008'!I23+'0025'!I23+'0028'!I23+'0062'!I23+'0008'!P23+'0025'!P23+'0028'!P23+'0062'!P23 -> 923500
B59: May | C59: ='0008'!J24+'0025'!J24+'0028'!J24+'0062'!J24+'0008'!Q24+'0025'!Q24+'0028'!Q24+'0062'!Q24 -> 741810.29 | D59: ='0008'!I24+'0025'!I24+'0028'!I24+'0062'!I24+'0008'!P24+'0025'!P24+'0028'!P24+'0062'!P24 -> 923500
B60: Jun | C60: ='0008'!J25+'0025'!J25+'0028'!J25+'0062'!J25+'0008'!Q25+'0025'!Q25+'0028'!Q25+'0062'!Q25 -> 726642.19 | D60: ='0008'!I25+'0025'!I25+'0028'!I25+'0062'!I25+'0008'!P25+'0025'!P25+'0028'!P25+'0062'!P25 -> 923500
B61: Jul | C61: ='0008'!J26+'0025'!J26+'0028'!J26+'0062'!J26+'0008'!Q26+'0025'!Q26+'0028'!Q26+'0062'!Q26 -> 737425.8 | D61: ='0008'!I26+'0025'!I26+'0028'!I26+'0062'!I26+'0008'!P26+'0025'!P26+'0028'!P26+'0062'!P26 -> 923500
B62: Aug | C62: ='0008'!J27+'0025'!J27+'0028'!J27+'0062'!J27+'0008'!Q27+'0025'!Q27+'0028'!Q27+'0062'!Q27 -> 765553.46 | D62: ='0008'!I27+'0025'!I27+'0028'!I27+'0062'!I27+'0008'!P27+'0025'!P27+'0028'!P27+'0062'!P27 -> 923500
B63: =B11 -> Mesa 0008 | C63: =E11 -> 0.80531267
B64: =B12 -> Polo 0025 | C64: =E12 -> 0.50642079
B65: =B13 -> Woodridge 0028 | C65: =E13 -> 0.81144323
B66: =B14 -> Dilley 0062 | C66: =E14 -> 0.85616123

Sheet 0008
B2: Food Variance % and Sales Budget Report Site 0008
B4: Food Margin
B5: Month | C5: GP % Before Discount | D5: Discount % of Sales | E5: Discount $ Total | F5: Target GP % After Discount | G5: Wastage $ | H5: Wastage % | I5: Sampling $ (Free Food) | J5: Sampling % (Free Food) | K5: Spoilage $ | L5: Spoilage % | M5: Logo Cups Adjustment $ | N5: Logo Cups, Adjustment % | O5: T. Target Margin After Adj. % | P5: INIR Net Margin | Q5: Shrink $ | R5: Shrink % | S5: SOS Avg (Average Kitchen Product Time) Mins | T5: Comments
B6: 46023 | C6: 0.675 | D6: 0.0258 | E6: 1123.46 | F6: =C6-D6 -> 0.6492 | G6: 1829.74 | H6: =G6/G20 -> 0.085557281 | I6: 670.28 | J6: =I6/G20 -> 0.031341794 | K6: 0 | L6: =K6/G20 -> 0 | M6: 93.98 | N6: =M6/G20 -> 0.0043944349 | O6: =F6-H6-J6-L6-N6 -> 0.52790649 | P6: 0.5232 | Q6: =R6*G20 -> -100.65364 | R6: =P6-O6 -> -0.0047064893 | S6: =422.65/60 -> 7.0441667
B7: 46054 | C7: 0.6684 | D7: 0.0309 | E7: 1137.6 | F7: =C7-D7 -> 0.6375 | G7: 1803.12 | H7: =G7/G21 -> 0.080393245 | I7: 537.34 | J7: =I7/G21 -> 0.023957644 | K7: 0 | L7: =K7/G21 -> 0 | M7: 119.2 | N7: =M7/G21 -> 0.0053146074 | O7: =F7-H7-J7-L7-N7 -> 0.5278345 | P7: 0.5745 | Q7: =R7*G21 -> 1046.6488 | R7: =P7-O7 -> 0.046665496 | S7: =436.66/60 -> 7.2776667
B8: 46082 | C8: 0.6723 | D8: 0.0305 | E8: 1619.36 | F8: =C8-D8 -> 0.6418 | G8: 2243.04 | H8: =G8/G22 -> 0.079454153 | I8: 732.45 | J8: =I8/G22 -> 0.025945233 | K8: 0 | L8: =K8/G22 -> 0 | M8: 193.32 | N8: =M8/G22 -> 0.0068478836 | O8: =F8-H8-J8-L8-N8 -> 0.52955273 | P8: 0.5731 | Q8: =R8*G22 -> 1229.3664 | R8: =P8-O8 -> 0.043547269 | S8: =370.9/60 -> 6.1816667
B9: 46113 | C9: 0.6652 | D9: 0.024 | E9: 1481.65 | F9: =C9-D9 -> 0.6412 | G9: 1895.97 | H9: =G9/G23 -> 0.066489499 | I9: 851.11 | J9: =I9/G23 -> 0.029847454 | K9: 0 | L9: =K9/G23 -> 0 | M9: 155.17 | N9: =M9/G23 -> 0.0054416344 | O9: =F9-H9-J9-L9-N9 -> 0.53942141 | P9: 0.6027 | Q9: =R9*G23 -> 1804.4098 | R9: =P9-O9 -> 0.063278587 | S9: =458.47/60 -> 7.6411667
B10: 46143 | C10: 0.6631 | D10: 0.0344 | E10: 1660.64 | F10: =C10-D10 -> 0.6287 | G10: 1785.94 | H10: =G10/G24 -> 0.067068717 | I10: 816.28 | J10: =I10/G24 -> 0.030654363 | K10: 0 | L10: =K10/G24 -> 0 | M10: 106.1 | N10: =M10/G24 -> 0.0039844513 | O10: =F10-H10-J10-L10-N10 -> 0.52699247 | P10: 0.5543 | Q10: =R10*G24 -> 727.15886 | R10: =P10-O10 -> 0.027307531 | S10: =469.23/60 -> 7.8205
B11: 46174 | C11: 0.6611 | D11: 0.0251 | E11: 1259.08 | F11: =C11-D11 -> 0.636 | G11: 1821 | H11: =G11/G25 -> 0.073070494 | I11: 678.32 | J11: =I11/G25 -> 0.027218659 | K11: 0 | L11: =K11/G25 -> 0 | M11: 141.06 | N11: =M11/G25 -> 0.0056602547 | O11: =F11-H11-J11-L11-N11 -> 0.53005059 | P11: 0.569 | Q11: =R11*G25 -> 970.66362 | R11: =P11-O11 -> 0.038949407 | S11: =453.08/60 -> 7.5513333
B12: 46204 | C12: 0.6511 | D12: 0.0227 | E12: 1077.79 | F12: =C12-D12 -> 0.6284 | G12: 1995.9 | H12: =G12/G26 -> 0.077233598 | I12: 921.91 | J12: =I12/G26 -> 0.035674346 | K12: 0 | L12: =K12/G26 -> 0 | M12: 140.48 | N12: =M12/G26 -> 0.0054360318 | O12: =F12-H12-J12-L12-N12 -> 0.51005602 | P12: 0.5689 | Q12: =R12*G26 -> 1520.6684 | R12: =P12-O12 -> 0.058843976 | S12: =454.64/60 -> 7.5773333
B13: 46235 | C13: 0.6432551 | D13: 0.024533 | E13: 1087.15 | F13: =C13-D13 -> 0.6187221 | G13: 1831.36 | H13: =G13/G27 -> 0.080847964 | I13: 925.85 | J13: =I13/G27 -> 0.040872951 | K13: 137.6 | L13: =K13/G27 -> 0.0060745456 | M13: 94.98 | N13: =M13/G27 -> 0.0041930258 | O13: =F13-H13-J13-L13-N13 -> 0.48673361 | P13: 0.5733 | Q13: =R13*G27 -> 1960.8931 | R13: =P13-O13 -> 0.086566387 | S13: =442.94/60 -> 7.3823333
B14: 46266 | F14: =C14-D14 -> 0 | H14: =G14/G28 -> #DIV/0! | J14: =I14/G28 -> #DIV/0! | L14: =K14/G28 -> #DIV/0! | N14: =M14/G28 -> #DIV/0! | O14: =F14-H14-J14-L14-N14 -> #DIV/0! | Q14: =R14*G28 -> #DIV/0! | R14: =P14-O14 -> #DIV/0!
B15: 46296 | F15: =C15-D15 -> 0 | H15: =G15/G29 -> #DIV/0! | J15: =I15/G29 -> #DIV/0! | L15: =K15/G29 -> #DIV/0! | N15: =M15/G29 -> #DIV/0! | O15: =F15-H15-J15-L15-N15 -> #DIV/0! | Q15: =R15*G29 -> #DIV/0! | R15: =P15-O15 -> #DIV/0!
B16: 46327 | F16: =C16-D16 -> 0 | H16: =G16/G30 -> #DIV/0! | J16: =I16/G30 -> #DIV/0! | L16: =K16/G30 -> #DIV/0! | N16: =M16/G30 -> #DIV/0! | O16: =F16-H16-J16-L16-N16 -> #DIV/0! | Q16: =R16*G30 -> #DIV/0! | R16: =P16-O16 -> #DIV/0!
B17: 46357 | F17: =C17-D17 -> 0 | H17: =G17/G31 -> #DIV/0! | J17: =I17/G31 -> #DIV/0! | L17: =K17/G31 -> #DIV/0! | N17: =M17/G31 -> #DIV/0! | O17: =F17-H17-J17-L17-N17 -> #DIV/0! | Q17: =R17*G31 -> #DIV/0! | R17: =P17-O17 -> #DIV/0!
B19: Month | C19: C-Store Retail Sales Budget | D19: C-Store Retail Sales Actual | E19: Variance | F19: Kitchen Sales Budget | G19: Kitchen Sales Actual | H19: Variance | I19: Total Sales Budget | J19: Total Sale (C-Stores & Kitchen) | K19: Variance | L19: Inventory Shrink $ - Kitchen | M19: Inventory Shrink % - Kitchen | N19: Inventory Shrink $ - C-Stores | O19: Inventory Shrink % - C-Stores | P19: Fountain Budget | Q19: Fountain Sales Actual | R19: Fountain Variance | S19: Fountain Inventory Over/Short | T19: Fountain INIR Net Margin
B20: 46023 | C20: 170000 | D20: 124352 | E20: =D20-C20 -> -45648 | F20: 38000 | G20: 21386.14 | H20: =G20-F20 -> -16613.86 | I20: =SUM(F20+C20) -> 208000 | J20: =D20+G20 -> 145738.14 | K20: =J20-I20 -> -62261.86 | L20: 1526.71 | M20: =L20/G20 -> 0.071387824 | N20: -1457 | O20: =N20/D20 -> -0.01171674 | P20: 3000 | Q20: 2409.86 | R20: =Q20-P20 -> -590.14 | S20: 168.24 | T20: 0.5283
B21: 46054 | C21: 170000 | D21: 124161 | E21: =D21-C21 -> -45839 | F21: 38000 | G21: 22428.75 | H21: =G21-F21 -> -15571.25 | I21: =SUM(F21+C21) -> 208000 | J21: =D21+G21 -> 146589.75 | K21: =J21-I21 -> -61410.25 | L21: 2453.35 | M21: =L21/G21 -> 0.10938416 | N21: -2376 | O21: =N21/D21 -> -0.019136444 | P21: 3000 | Q21: 2369.97 | R21: =Q21-P21 -> -630.03 | S21: -698.07 | T21: 0.1809
B22: 46082 | C22: 170000 | D22: 152697 | E22: =D22-C22 -> -17303 | F22: 38000 | G22: 28230.62 | H22: =G22-F22 -> -9769.38 | I22: 208000 | J22: =D22+G22 -> 180927.62 | K22: =J22-I22 -> -27072.38 | L22: 3187.15 | M22: =L22/G22 -> 0.11289692 | N22: -3306 | O22: =N22/D22 -> -0.02165072 | P22: 3000 | Q22: 3084.05 | R22: =Q22-P22 -> 84.05 | S22: -1096.08 | T22: 0.1386
B23: 46113 | C23: 170000 | D23: 141512 | E23: =D23-C23 -> -28488 | F23: 38000 | G23: 28515.33 | H23: =G23-F23 -> -9484.67 | I23: 208000 | J23: =D23+G23 -> 170027.33 | K23: =J23-I23 -> -37972.67 | L23: 3701.87 | M23: =L23/G23 -> 0.12982035 | N23: -2284 | O23: =N23/D23 -> -0.016139974 | P23: 3000 | Q23: 2959.3 | R23: =Q23-P23 -> -40.7 | S23: -595.11 | T23: 0.2776
B24: 46143 | C24: 170000 | D24: 151524 | E24: =D24-C24 -> -18476 | F24: 38000 | G24: 26628.51 | H24: =G24-F24 -> -11371.49 | I24: 208000 | J24: =D24+G24 -> 178152.51 | K24: =J24-I24 -> -29847.49 | L24: 2272.71 | M24: =L24/G24 -> 0.085348748 | N24: -2165 | O24: =N24/D24 -> -0.014288166 | P24: 3000 | Q24: 3153.49 | R24: =Q24-P24 -> 153.49 | S24: -137.05 | T24: 0.407
B25: 46174 | C25: 170000 | D25: 146542 | E25: =D25-C25 -> -23458 | F25: 38000 | G25: 24921.14 | H25: =G25-F25 -> -13078.86 | I25: 208000 | J25: =D25+G25 -> 171463.14 | K25: =J25-I25 -> -36536.86 | L25: 2489.87 | M25: =L25/G25 -> 0.099909956 | N25: -4013 | O25: =N25/D25 -> -0.027384641 | P25: 3000 | Q25: 3485.76 | R25: =Q25-P25 -> 485.76 | S25: -420.9 | T25: 0.34
B26: 46204 | C26: 170000 | D26: 145683 | E26: =D26-C26 -> -24317 | F26: 38000 | G26: 25842.38 | H26: =G26-F26 -> -12157.62 | I26: 208000 | J26: =D26+G26 -> 171525.38 | K26: =J26-I26 -> -36474.62 | L26: 2687.86 | M26: =L26/G26 -> 0.10400977 | N26: -5453 | O26: =N26/D26 -> -0.037430586 | P26: 3000 | Q26: 3861.31 | R26: =Q26-P26 -> 861.31 | S26: -144.99 | T26: 0.417
B27: 46235 | C27: 170000 | D27: 146971 | E27: =D27-C27 -> -23029 | F27: 38000 | G27: 22651.9 | H27: =G27-F27 -> -15348.1 | I27: 208000 | J27: =D27+G27 -> 169622.9 | K27: =J27-I27 -> -38377.1 | L27: 2865.42 | M27: =L27/G27 -> 0.126498 | N27: 915 | O27: =N27/D27 -> 0.006225718 | P27: 3000 | Q27: 3997.27 | R27: =Q27-P27 -> 997.27 | S27: 6.29 | T27: 0.4372
B28: 46266 | C28: 170000 | E28: =D28-C28 -> -170000 | F28: 38000 | H28: =G28-F28 -> -38000 | I28: 208000 | J28: =D28+G28 -> 0 | K28: =J28-I28 -> -208000 | M28: =L28/G28 -> #DIV/0! | O28: =N28/D28 -> #DIV/0! | P28: 3000 | R28: =Q28-P28 -> -3000
B29: 46296 | C29: 170000 | E29: =D29-C29 -> -170000 | F29: 38000 | H29: =G29-F29 -> -38000 | I29: 208000 | J29: =D29+G29 -> 0 | K29: =J29-I29 -> -208000 | M29: =L29/G29 -> #DIV/0! | O29: =N29/D29 -> #DIV/0! | P29: 3000 | R29: =Q29-P29 -> -3000
B30: 46327 | C30: 170000 | E30: =D30-C30 -> -170000 | F30: 38000 | H30: =G30-F30 -> -38000 | I30: 208000 | J30: =D30+G30 -> 0 | K30: =J30-I30 -> -208000 | M30: =L30/G30 -> #DIV/0! | O30: =N30/D30 -> #DIV/0! | P30: 3000 | R30: =Q30-P30 -> -3000
B31: 46357 | C31: 170000 | E31: =D31-C31 -> -170000 | F31: 38000 | H31: =G31-F31 -> -38000 | I31: 208000 | J31: =D31+G31 -> 0 | K31: =J31-I31 -> -208000 | M31: =L31/G31 -> #DIV/0! | O31: =N31/D31 -> #DIV/0! | P31: 3000 | R31: =Q31-P31 -> -3000
B33: Month | C33: Total Customer # (Fuel, C-Store & Kitchen_ | D33: Crind | E33: DR MOP | F33: Total Crind Debit & Credit | G33: Total Customer # (C-Stores & Kitchen) | H33: Average Customer # (C-Stores & Kitchen) | I33: Average Sales Per Customer (Cstore & Kitchen) | J33: No of Days in a Month | K33: Comments
C34: A | D34: B | E34: C | F34: D=B+C | G34: E=A-D | H34: F=E / H | I34: G=Total Sales/E | J34: H | K34: I
B35: 46023 | C35: 27412 | D35: 3251 | E35: 5929 | F35: =D35+E35 -> 9180 | G35: =C35-F35 -> 18232 | H35: =G35/J35 -> 588.12903 | I35: =J20/G35 -> 7.9935355 | J35: 31 | K35: Can delete/Hide this section-just need the two numbers that I put above this
B36: 46054 | C36: 27718 | D36: 3539 | E36: 6380 | F36: =D36+E36 -> 9919 | G36: =C36-F36 -> 17799 | H36: =G36/J36 -> 635.67857 | I36: =J21/G36 -> 8.2358419 | J36: 28
B37: 46082 | C37: 35272 | D37: 4659 | E37: 8054 | F37: =D37+E37 -> 12713 | G37: =C37-F37 -> 22559 | H37: =G37/J37 -> 727.70968 | I37: =J22/G37 -> 8.0201968 | J37: 31
B38: 46113 | C38: 35412 | D38: 4707 | E38: 8042 | F38: =D38+E38 -> 12749 | G38: =C38-F38 -> 22663 | H38: =G38/J38 -> 755.43333 | I38: =J23/G38 -> 7.5024194 | J38: 30
B39: 46143 | C39: 38379 | D39: 5278 | E39: 8932 | F39: =D39+E39 -> 14210 | G39: =C39-F39 -> 24169 | H39: =G39/J39 -> 779.64516 | I39: =J24/G39 -> 7.3711163 | J39: 31
B40: 46174 | C40: 34209 | D40: 4196 | E40: 8014 | F40: =D40+E40 -> 12210 | G40: =C40-F40 -> 21999 | H40: =G40/J40 -> 733.3 | I40: =J25/G40 -> 7.7941334 | J40: 30
B41: 46204 | C41: 34708 | D41: 4461 | E41: 8389 | F41: =D41+E41 -> 12850 | G41: =C41-F41 -> 21858 | H41: =G41/J41 -> 705.09677 | I41: =J26/G41 -> 7.8472587 | J41: 31
B42: 46235 | C42: 35768 | D42: 4832 | E42: 8850 | F42: =D42+E42 -> 13682 | G42: =C42-F42 -> 22086 | H42: =G42/J42 -> 712.45161 | I42: =J27/G42 -> 7.6801096 | J42: 31
B43: 46266 | F43: =D43+E43 -> 0 | G43: =C43-F43 -> 0 | H43: =G43/J43 -> 0 | I43: =J28/G43 -> #DIV/0! | J43: 30
B44: 46296 | F44: =D44+E44 -> 0 | G44: =C44-F44 -> 0 | H44: =G44/J44 -> 0 | I44: =J29/G44 -> #DIV/0! | J44: 31
...

Sheet Sheet2
S9: 327.01
S10: 371.57
S11: 353.1
S12: 358.52
S14: 481.79
S15: 384.71
S16: 372.48
S17: 445.3
S18: 373.36
S19: 339.48
S20: 342.98
S21: 357.92
... S27: 351.89
S28: 389.88 | W28: 358
S29: 319.42 | W29: =W28/60 -> 5.9666667
S30: 339.11
S31: 413.51
S32: 415.43
S33: 366.17
S34: 372.28
S35: 428.75
S36: 423.78
S37: 404.48
S38: 394.9
S40: =SUM(S9:S39) -> 11190.83

Sheet 0028
B2: Food Variance % and Sales Budget Report Site 0028
B4: Food Margin
B5: Month | C5: GP % Before Discount | D5: Discount % of Sales | E5: Discount $ Total | F5: Target GP % After Discount | G5: Wastage $ | H5: Wastage % | I5: Sampling $ (Free Food) | J5: Sampling % (Free Food) | K5: Spoilage $ | L5: Spoilage % | M5: Logo Cups Adjustment $ | N5: Logo Cups, Adjustment % | O5: T. Target Margin After Adj. % | P5: INIR Net Margin | Q5: Shrink $ | R5: Shrink % | S5: SOS Avg (Average Kitchen Product Time) Mins | T5: Comments
B6: 46023 | C6: 0.6772 | D6: 0.025 | E6: 1206.91 | F6: =C6-D6 -> 0.6522 | G6: 618.7 | H6: =G6/G20 -> 0.029520665 | I6: 250 | J6: =I6/G20 -> 0.011928505 | K6: 0 | L6: =K6/G20 -> 0 | M6: 109.88 | N6: =M6/G20 -> 0.0052428167 | O6: =F6-H6-J6-L6-N6 -> 0.60550801 | P6: 0.4073 | Q6: =R6*G20 -> -4154.0832 | R6: =P6-O6 -> -0.19820801 | S6: =387.74/60 -> 6.4623333
B7: 46054 | C7: 0.6762 | D7: 0.0339 | E7: 1911.63 | F7: =C7-D7 -> 0.6423 | G7: 1851.32 | H7: =G7/G21 -> 0.074954017 | I7: 396.39 | J7: =I7/G21 -> 0.016048561 | K7: 0 | L7: =K7/G21 -> 0 | M7: 115.64 | N7: =M7/G21 -> 0.0046818932 | O7: =F7-H7-J7-L7-N7 -> 0.54661553 | P7: 0.4898 | Q7: =R7*G21 -> -1403.31 | R7: =P7-O7 -> -0.056815528 | S7: =386.91/60 -> 6.4485
B8: 46082 | C8: 0.6713 | D8: 0.0255 | E8: 2114.17 | F8: =C8-D8 -> 0.6458 | G8: 1200 | H8: =G8/G22 -> 0.043859922 | I8: 955 | J8: =I8/G22 -> 0.034905188 | K8: 0 | L8: =K8/G22 -> 0 | M8: 117.62 | N8: =M8/G22 -> 0.0042990033 | O8: =F8-H8-J8-L8-N8 -> 0.56273589 | P8: 0.5038 | Q8: =R8*G22 -> -1612.4759 | R8: =P8-O8 -> -0.058935887 | S8: =314.28/60 -> 5.238
B9: 46113 | C9: 0.6653 | D9: 0.0326 | E9: 2553.67 | F9: =C9-D9 -> 0.6327 | G9: 1203 | H9: =G9/G23 -> 0.044917273 | I9: 1255.45 | J9: =I9/G23 -> 0.046875636 | K9: 0 | L9: =K9/G23 -> 0 | M9: 159.96 | N9: =M9/G23 -> 0.0059725411 | O9: =F9-H9-J9-L9-N9 -> 0.53493455 | P9: 0.5078 | Q9: =R9*G23 -> -726.73299 | R9: =P9-O9 -> -0.02713455 | S9: =319.38/60 -> 5.323
B10: 46143 | C10: 0.6247 | D10: 0.0421 | E10: 2816.75 | F10: =C10-D10 -> 0.5826 | G10: 1887.53 | H10: =G10/G24 -> 0.071911822 | I10: 1284.42 | J10: =I10/G24 -> 0.048934312 | K10: 0 | L10: =K10/G24 -> 0 | M10: 123.19 | N10: =M10/G24 -> 0.0046933386 | O10: =F10-H10-J10-L10-N10 -> 0.45706053 | P10: 0.474 | Q10: =R10*G24 -> 444.62458 | R10: =P10-O10 -> 0.016939473 | S10: =345.4/60 -> 5.7566667
B11: 46174 | C11: 0.6612 | D11: 0.0491 | E11: 2925.16 | F11: =C11-D11 -> 0.6121 | G11: 1833.28 | H11: =G11/G25 -> 0.076472698 | I11: 816.95 | J11: =I11/G25 -> 0.034077921 | K11: 449.81 | L11: =K11/G25 -> 0.018763192 | M11: 123.99 | N11: =M11/G25 -> 0.0051720686 | O11: =F11-H11-J11-L11-N11 -> 0.47761412 | P11: 0.478 | Q11: =R11*G25 -> 9.2507 | R11: =P11-O11 -> 0.00038587995 | S11: =357.14/60 -> 5.9523333
B12: 46204 | C12: 0.6476 | D12: 0.0432 | E12: 2199.32 | F12: =C12-D12 -> 0.6044 | G12: 1879.4 | H12: =G12/G26 -> 0.076353989 | I12: 1345.16 | J12: =I12/G26 -> 0.054649533 | K12: 0 | L12: =K12/G26 -> 0 | M12: 97.96 | N12: =M12/G26 -> 0.0039798004 | O12: =F12-H12-J12-L12-N12 -> 0.46941668 | P12: 0.4342 | Q12: =R12*G26 -> -866.83386 | R12: =P12-O12 -> -0.035216677 | S12: =358.1/60 -> 5.9683333
B13: 46235 | C13: 0.64823737 | D13: 0.0489762 | E13: 2614.19 | F13: =C13-D13 -> 0.59926117 | G13: 1900 | H13: =G13/G27 -> 0.079989963 | I13: 1283.76 | J13: =I13/G27 -> 0.054046271 | K13: 0 | L13: =K13/G27 -> 0 | M13: 102.73 | N13: =M13/G27 -> 0.004324931 | O13: =F13-H13-J13-L13-N13 -> 0.4609 | P13: 0.5377 | Q13: =R13*G27 -> 1824.2288 | R13: =P13-O13 -> 0.076799998 | S13: =329.83/60 -> 5.4971667
B14: 46266 | F14: =C14-D14 -> 0 | H14: =G14/G28 -> #DIV/0! | J14: =I14/G28 -> #DIV/0! | K14: 0 | L14: =K14/G28 -> #DIV/0! | N14: =M14/G28 -> #DIV/0! | O14: =F14-H14-J14-L14-N14 -> #DIV/0! | Q14: =R14*G28 -> #DIV/0! | R14: =P14-O14 -> #DIV/0!
B15: 46296 | F15: =C15-D15 -> 0 | H15: =G15/G29 -> #DIV/0! | J15: =I15/G29 -> #DIV/0! | K15: 0 | L15: =K15/G29 -> #DIV/0! | N15: =M15/G29 -> #DIV/0! | O15: =F15-H15-J15-L15-N15 -> #DIV/0! | Q15: =R15*G29 -> #DIV/0! | R15: =P15-O15 -> #DIV/0!
B16: 46327 | F16: =C16-D16 -> 0 | H16: =G16/G30 -> #DIV/0! | J16: =I16/G30 -> #DIV/0! | K16: 0 | L16: =K16/G30 -> #DIV/0! | N16: =M16/G30 -> #DIV/0! | O16: =F16-H16-J16-L16-N16 -> #DIV/0! | Q16: =R16*G30 -> #DIV/0! | R16: =P16-O16 -> #DIV/0!
B17: 46357 | F17: =C17-D17 -> 0 | H17: =G17/G31 -> #DIV/0! | J17: =I17/G31 -> #DIV/0! | K17: 0 | L17: =K17/G31 -> #DIV/0! | N17: =M17/G31 -> #DIV/0! | O17: =F17-H17-J17-L17-N17 -> #DIV/0! | Q17: =R17*G31 -> #DIV/0! | R17: =P17-O17 -> #DIV/0!
B19: Month | C19: C-Store Retail Sales Budget | D19: C-Store Retail Sales Actual | E19: Variance | F19: Kitchen Sales Budget | G19: Kitchen Sales Actual | H19: Variance | I19: Total Sales Budget | J19: Total Sale (C-Stores & Kitchen) | K19: Variance | L19: Inventory Shrink $ - Kitchen | M19: Inventory Shrink % - Kitchen | N19: Inventory Shrink $ - C-Stores | O19: Inventory Shrink % - C-Stores | P19: Fountain Budget | Q19: Fountain Sales Actual | R19: Fountain Variance | S19: Fountain Inventory Over/Short | T19: Fountain INIR Net Margin
B20: 46023 | C20: 185000 | D20: 141127 | E20: =D20-C20 -> -43873 | F20: 42000 | G20: 20958.2 | H20: =G20-F20 -> -21041.8 | I20: =SUM(C20+F20) -> 227000 | J20: =G20+D20 -> 162085.2 | K20: =J20-I20 -> -64914.8 | L20: -2527.51 | M20: =L20/G20 -> -0.12059767 | N20: -4400 | O20: =N20/D20 -> -0.031177592 | P20: 6000 | Q20: 5242.6 | R20: =Q20-P20 -> -757.4 | S20: -670.3 | T20: 0.3036
B21: 46054 | C21: 185000 | D21: 139490 | E21: =D21-C21 -> -45510 | F21: 42000 | G21: 24699.41 | H21: =G21-F21 -> -17300.59 | I21: =SUM(C21+F21) -> 227000 | J21: =G21+D21 -> 164189.41 | K21: =J21-I21 -> -62810.59 | L21: 241.84 | M21: =L21/G21 -> 0.009791327 | N21: -1720 | O21: =N21/D21 -> -0.012330633 | P21: 6000 | Q21: 5546.57 | R21: =Q21-P21 -> -453.43 | S21: 352.47 | T21: 0.4948
B22: 46082 | C22: 185000 | D22: 162478 | E22: =D22-C22 -> -22522 | F22: 42000 | G22: 27359.83 | H22: =G22-F22 -> -14640.17 | I22: =SUM(C22+F22) -> 227000 | J22: =G22+D22 -> 189837.83 | K22: =J22-I22 -> -37162.17 | L22: 258.58 | M22: =L22/G22 -> 0.0094510821 | N22: -2102 | O22: =N22/D22 -> -0.012937136 | P22: 6000 | Q22: 6266.45 | R22: =Q22-P22 -> 266.45 | S22: -169.85 | T22: 0.4011
B23: 46113 | C23: 185000 | D23: 157600 | E23: =D23-C23 -> -27400 | F23: 42000 | G23: 26782.57 | H23: =G23-F23 -> -15217.43 | I23: =SUM(C23+F23) -> 227000 | J23: =G23+D23 -> 184382.57 | K23: =J23-I23 -> -42617.43 | L23: 999.1 | M23: =L23/G23 -> 0.037304112 | N23: -240 | O23: =N23/D23 -> -0.0015228426 | P23: 6000 | Q23: 5831.11 | R23: =Q23-P23 -> -168.89 | S23: 671.8 | T23: 0.5564
B24: 46143 | C24: 185000 | D24: 168818 | E24: =D24-C24 -> -16182 | F24: 42000 | G24: 26247.84 | H24: =G24-F24 -> -15752.16 | I24: =SUM(C24+F24) -> 227000 | J24: =G24+D24 -> 195065.84 | K24: =J24-I24 -> -31934.16 | L24: 899.81 | M24: =L24/G24 -> 0.034281297 | N24: -2665 | O24: =N24/D24 -> -0.015786231 | P24: 6000 | Q24: 6270.69 | R24: =Q24-P24 -> 270.69 | S24: -859.75 | T24: 0.2924
B25: 46174 | C25: 185000 | D25: 164054 | E25: =D25-C25 -> -20946 | F25: 42000 | G25: 23973 | H25: =G25-F25 -> -18027 | I25: =SUM(C25+F25) -> 227000 | J25: =G25+D25 -> 188027 | K25: =J25-I25 -> -38973 | L25: 1222.36 | M25: =L25/G25 -> 0.050989029 | N25: -2281 | O25: =N25/D25 -> -0.013903958 | P25: 6000 | Q25: 5918.32 | R25: =Q25-P25 -> -81.68 | S25: -553.64 | T25: 0.3379
B26: 46204 | C26: 185000 | D26: 164426 | E26: =D26-C26 -> -20574 | F26: 42000 | G26: 24614.3 | H26: =G26-F26 -> -17385.7 | I26: =SUM(C26+F26) -> 227000 | J26: =G26+D26 -> 189040.3 | K26: =J26-I26 -> -37959.7 | L26: -794.96 | M26: =L26/G26 -> -0.032296673 | N26: -5909 | O26: =N26/D26 -> -0.035937139 | P26: 6000 | Q26: 6335.29 | R26: =Q26-P26 -> 335.29 | S26: -159.69 | T26: 0.398
B27: 46235 | C27: 185000 | D27: 167643 | E27: =D27-C27 -> -17357 | F27: 42000 | G27: 23752.98 | H27: =G27-F27 -> -18247.02 | I27: =SUM(C27+F27) -> 227000 | J27: =G27+D27 -> 191395.98 | K27: =J27-I27 -> -35604.02 | L27: 2752.39 | M27: =L27/G27 -> 0.11587557 | N27: -991 | O27: =N27/D27 -> -0.0059113712 | P27: 6000 | Q27: 7095.03 | R27: =Q27-P27 -> 1095.03 | S27: -5.56 | T27: 0.4209
B28: 46266 | C28: 185000 | E28: =D28-C28 -> -185000 | F28: 42000 | H28: =G28-F28 -> -42000 | I28: =SUM(C28+F28) -> 227000 | J28: =G28+D28 -> 0 | K28: =J28-I28 -> -227000 | M28: =L28/G28 -> #DIV/0! | O28: =N28/D28 -> #DIV/0! | P28: 6000 | R28: =Q28-P28 -> -6000
B29: 46296 | C29: 185000 | E29: =D29-C29 -> -185000 | F29: 42000 | H29: =G29-F29 -> -42000 | I29: =SUM(C29+F29) -> 227000 | J29: =G29+D29 -> 0 | K29: =J29-I29 -> -227000 | M29: =L29/G29 -> #DIV/0! | O29: =N29/D29 -> #DIV/0! | P29: 6000 | R29: =Q29-P29 -> -6000
B30: 46327 | C30: 185000 | E30: =D30-C30 -> -185000 | F30: 42000 | H30: =G30-F30 -> -42000 | I30: =SUM(C30+F30) -> 227000 | J30: =G30+D30 -> 0 | K30: =J30-I30 -> -227000 | M30: =L30/G30 -> #DIV/0! | O30: =N30/D30 -> #DIV/0! | P30: 6000 | R30: =Q30-P30 -> -6000
B31: 46357 | C31: 185000 | E31: =D31-C31 -> -185000 | F31: 42000 | H31: =G31-F31 -> -42000 | I31: =SUM(C31+F31) -> 227000 | J31: =G31+D31 -> 0 | K31: =J31-I31 -> -227000 | M31: =L31/G31 -> #DIV/0! | O31: =N31/D31 -> #DIV/0! | P31: 6000 | R31: =Q31-P31 -> -6000
B33: Month | C33: Total Customer # (Fuel, C-Store & Kitchen_ | D33: Crind | E33: DR MOP | F33: Total Crind Debit & Credit | G33: Total Customer # (C-Stores & Kitchen) | H33: Average Customer # (C-Stores & Kitchen) | I33: Average Sales Per Customer (Cstore & Kitchen) | J33: No of Days in a Month | K33: Comments | Q33: Inir Retail
C34: A | D34: B | E34: C | F34: D=B+C | G34: E=A-D | H34: F=E / H | I34: G=Total Sales/E | J34: H | K34: I | Q34: enter
B35: 46023 | C35: 35837 | D35: 7401 | E35: 17745 | F35: =D35+E35 -> 25146 | G35: =C35-F35 -> 10691 | H35: =G35/J35 -> 344.87097 | I35: =J20/G35 -> 15.160902 | J35: 31 | K35: Can delete/Hide this section-just need the two numbers that I put above this | Q35: Shortage CStores
B36: 46054 | C36: 36215 | D36: 7418 | E36: 18029 | F36: =D36+E36 -> 25447 | G36: =C36-F36 -> 10768 | H36: =G36/J36 -> 384.57143 | I36: =J21/G36 -> 15.247902 | J36: 28
B37: 46082 | C37: 43653 | D37: 8947 | E37: 21203 | F37: =D37+E37 -> 30150 | G37: =C37-F37 -> 13503 | H37: =G37/J37 -> 435.58065 | I37: =J22/G37 -> 14.058937 | J37: 31
B38: 46113 | C38: 43324 | D38: 8991 | E38: 21565 | F38: =D38+E38 -> 30556 | G38: =C38-F38 -> 12768 | H38: =G38/J38 -> 425.6 | I38: =J23/G38 -> 14.440991 | J38: 30
B39: 46143 | C39: 45289 | D39: 8988 | E39: 21627 | F39: =D39+E39 -> 30615 | G39: =C39-F39 -> 14674 | H39: =G39/J39 -> 473.35484 | I39: =J24/G39 -> 13.293297 | J39: 31
B40: 46174 | C40: 42683 | D40: 7188 | E40: 19131 | F40: =D40+E40 -> 26319 | G40: =C40-F40 -> 16364 | H40: =G40/J40 -> 545.46667 | I40: =J25/G40 -> 11.490284 | J40: 30
B41: 46204 | C41: 43679 | D41: 7884 | E41: 19062 | F41: =D41+E41 -> 26946 | G41: =C41-F41 -> 16733 | H41: =G41/J41 -> 539.77419 | I41: =J26/G41 -> 11.297454 | J41: 31
B42: 46235 | C42: 44777 | D42: 8312 | E42: 21313 | F42: =D42+E42 -> 29625 | G42: =C42-F42 -> 15152 | H42: =G42/J42 -> 488.77419 | I42: =J27/G42 -> 12.63173 | J42: 31
B43: 46266 | F43: =D43+E43 -> 0 | G43: =C43-F43 -> 0 | H43: =G43/J43 -> 0 | I43: =J28/G43 -> #DIV/0! | J43: 30
B44: 46296 | F44: =D44+E44 -> 0 | G44: =C44-F44 -> 0 | H44: =G44/J44 -> 0 | I44: =J29/G44 -> #DIV/0! | J44: 31
...

Sheet 0062
B2: Food Variance % and Sales Budget Report Site 0062
B4: Food Margin
B5: Month | C5: GP % Before Discount | D5: Discount % of Sales | E5: Discount $ Total | F5: Target GP % After Discount | G5: Wastage $ | H5: Wastage % | I5: Sampling $ (Free Food) | J5: Sampling % (Free Food) | K5: Spoilage $ | L5: Spoilage % | M5: Logo Cups Adjustment $ | N5: Logo Cups, Adjustment % | O5: T. Target Margin After Adj. % | P5: INIR Net Margin | Q5: Shrink $ | R5: Shrink % | S5: SOS Avg (Average Kitchen Product Time) Mins | T5: Comments
B6: 46023 | C6: 0.6483 | D6: 0.0226 | E6: 1357.5 | F6: =C6-D6 -> 0.6257 | G6: 1661.54 | H6: =G6/G20 -> 0.065919609 | I6: 636.49 | J6: =I6/G20 -> 0.025251978 | K6: 0 | L6: =K6/G20 -> 0 | M6: -500.56 | N6: =M6/G20 -> -0.019859118 | O6: =F6-H6-J6-L6-N6 -> 0.55438753 | P6: 0.4881 | Q6: =R6*G20 -> -1670.8137 | R6: =P6-O6 -> -0.066287531 | S6: =546.78/60 -> 9.113
B7: 46054 | C7: 0.645 | D7: 0.0332 | E7: 2155.74 | F7: =C7-D7 -> 0.6118 | G7: 2243.19 | H7: =G7/G21 -> 0.078565955 | I7: 285 | J7: =I7/G21 -> 0.0099818995 | K7: 0 | L7: =K7/G21 -> 0 | M7: 170.72 | N7: =M7/G21 -> 0.0059793329 | O7: =F7-H7-J7-L7-N7 -> 0.51727281 | P7: 0.5165 | Q7: =R7*G21 -> -22.065104 | R7: =P7-O7 -> -0.00077281281 | S7: =510.28/60 -> 8.5046667
B8: 46082 | C8: 0.6435 | D8: 0.0402 | E8: 2187.85 | F8: =C8-D8 -> 0.6033 | G8: 2181.83 | H8: =G8/G22 -> 0.064622517 | I8: 450 | J8: =I8/G22 -> 0.013328322 | K8: 0 | L8: =K8/G22 -> 0 | M8: 237.08 | N8: =M8/G22 -> 0.0070219523 | O8: =F8-H8-J8-L8-N8 -> 0.51832721 | P8: 0.5318 | Q8: =R8*G22 -> 454.87767 | R8: =P8-O8 -> 0.013472791 | S8: =470.74/60 -> 7.8456667
B9: 46113 | C9: 0.6498 | D9: 0.0411 | E9: 2837.07 | F9: =C9-D9 -> 0.6087 | G9: 900 | H9: =G9/G23 -> 0.025052576 | I9: 885 | J9: =I9/G23 -> 0.024635033 | K9: 0 | L9: =K9/G23 -> 0 | M9: 244.82 | N9: =M9/G23 -> 0.0068148573 | O9: =F9-H9-J9-L9-N9 -> 0.55219753 | P9: 0.4918 | Q9: =R9*G23 -> -2169.7482 | R9: =P9-O9 -> -0.060397534 | S9: =470.74/60 -> 7.8456667
B10: 46143 | C10: 0.6728 | D10: 0.0428 | E10: 2939.29 | F10: =C10-D10 -> 0.63 | G10: 1500 | H10: =G10/G24 -> 0.036276678 | I10: 850 | J10: =I10/G24 -> 0.020556784 | K10: 0 | L10: =K10/G24 -> 0 | M10: 277.05 | N10: =M10/G24 -> 0.0067003024 | O10: =F10-H10-J10-L10-N10 -> 0.56646624 | P10: 0.5806 | Q10: =R10*G24 -> 584.41533 | R10: =P10-O10 -> 0.014133764 | S10: =470.74/60 -> 7.8456667 | T10: OLD
B11: 46174 | C11: 0.6488 | D11: 0.0415 | E11: 3144.43 | F11: =C11-D11 -> 0.6073 | G11: 4000.35 | H11: =G11/G25 -> 0.097459977 | I11: 600 | J11: =I11/G25 -> 0.014617717 | K11: 0 | L11: =K11/G25 -> 0 | M11: 207.69 | N11: =M11/G25 -> 0.0050599229 | O11: =F11-H11-J11-L11-N11 -> 0.49016238 | P11: 0.485 | Q11: =R11*G25 -> -211.89558 | R11: =P11-O11 -> -0.005162383 | S11: =620.99/60 -> 10.349833
B12: 46204 | C12: 0.652 | D12: 0.0456 | E12: 2541.18 | F12: =C12-D12 -> 0.6064 | G12: 550.04 | H12: =G12/G26 -> 0.014180726 | I12: 400 | J12: =I12/G26 -> 0.010312505 | K12: 0 | L12: =K12/G26 -> 0 | M12: 225.56 | N12: =M12/G26 -> 0.0058152216 | O12: =F12-H12-J12-L12-N12 -> 0.57609155 | P12: 0.4966 | Q12: =R12*G26 -> -3083.307 | R12: =P12-O12 -> -0.079491548 | S12: =590.86/60 -> 9.8476667
B13: 46235 | C13: 0.6520766 | D13: 0.0454256 | E13: 3375.48 | F13: =C13-D13 -> 0.606651 | G13: 1449.7 | H13: =G13/G27 -> 0.033041159 | I13: 715 | J13: =I13/G27 -> 0.016296081 | K13: 0 | L13: =K13/G27 -> 0 | M13: 243.29 | N13: =M13/G27 -> 0.0055449979 | O13: =F13-H13-J13-L13-N13 -> 0.55176876 | P13: 0.5035 | Q13: =R13*G27 -> -2117.82 | R13: =P13-O13 -> -0.048268763 | S13: =590.86/60 -> 9.8476667 | T13: OLD
B14: 46266 | F14: =C14-D14 -> 0 | H14: =G14/G28 -> #DIV/0! | J14: =I14/G28 -> #DIV/0! | K14: 0 | L14: =K14/G28 -> #DIV/0! | N14: =M14/G28 -> #DIV/0! | O14: =F14-H14-J14-L14-N14 -> #DIV/0! | Q14: =R14*G28 -> #DIV/0! | R14: =P14-O14 -> #DIV/0!
B15: 46296 | F15: =C15-D15 -> 0 | H15: =G15/G29 -> #DIV/0! | J15: =I15/G29 -> #DIV/0! | K15: 0 | L15: =K15/G29 -> #DIV/0! | N15: =M15/G29 -> #DIV/0! | O15: =F15-H15-J15-L15-N15 -> #DIV/0! | Q15: =R15*G29 -> #DIV/0! | R15: =P15-O15 -> #DIV/0!
B16: 46327 | F16: =C16-D16 -> 0 | H16: =G16/G30 -> #DIV/0! | J16: =I16/G30 -> #DIV/0! | K16: 0 | L16: =K16/G30 -> #DIV/0! | N16: =M16/G30 -> #DIV/0! | O16: =F16-H16-J16-L16-N16 -> #DIV/0! | Q16: =R16*G30 -> #DIV/0! | R16: =P16-O16 -> #DIV/0!
B17: 46357 | F17: =C17-D17 -> 0 | H17: =G17/G31 -> #DIV/0! | J17: =I17/G31 -> #DIV/0! | K17: 0 | L17: =K17/G31 -> #DIV/0! | N17: =M17/G31 -> #DIV/0! | O17: =F17-H17-J17-L17-N17 -> #DIV/0! | Q17: =R17*G31 -> #DIV/0! | R17: =P17-O17 -> #DIV/0!
B19: Month | C19: C-Store Retail Sales Budget | D19: C-Store Retail Sales Actual | E19: Variance | F19: Kitchen Sales Budget | G19: Kitchen Sales Actual | H19: Variance | I19: Total Sales Budget | J19: Total Sale (C-Stores & Kitchen) | K19: Variance | L19: Inventory Shrink $ - Kitchen | M19: Inventory Shrink % - Kitchen | N19: Inventory Shrink $ - C-Stores | O19: Inventory Shrink % - C-Stores | P19: Fountain Budget | Q19: Fountain Sales Actual | R19: Fountain Variance | S19: Fountain Inventory Over/Short | T19: Fountain INIR Net Margin
B20: 46023 | C20: 205000 | D20: 130836 | E20: =D20-C20 -> -74164 | F20: 35000 | G20: 25205.55 | H20: =G20-F20 -> -9794.45 | I20: =F20+C20 -> 240000 | J20: =G20+D20 -> 156041.55 | K20: =J20-I20 -> -83958.45 | L20: -427.66 | M20: =L20/G20 -> -0.016966898 | N20: -448 | O20: =N20/D20 -> -0.003424134 | P20: 6000 | Q20: 6339.68 | R20: =Q20-P20 -> 339.68 | S20: 547.58 | T20: 0.5185
B21: 46054 | C21: 205000 | D21: 133345 | E21: =D21-C21 -> -71655 | F21: 35000 | G21: 28551.68 | H21: =G21-F21 -> -6448.32 | I21: =F21+C21 -> 240000 | J21: =G21+D21 -> 161896.68 | K21: =J21-I21 -> -78103.32 | L21: 1199.69 | M21: =L21/G21 -> 0.042018193 | N21: -4776 | O21: =N21/D21 -> -0.035816866 | P21: 6000 | Q21: 6315.71 | R21: =Q21-P21 -> 315.71 | S21: 182.96 | T21: 0.4695
B22: 46082 | C22: 205000 | D22: 157878 | E22: =D22-C22 -> -47122 | F22: 35000 | G22: 33762.69 | H22: =G22-F22 -> -1237.31 | I22: 240000 | J22: =G22+D22 -> 191640.69 | K22: =J22-I22 -> -48359.31 | L22: 896.41 | M22: =L22/G22 -> 0.026550313 | N22: -1854 | O22: =N22/D22 -> -0.011743245 | P22: 6000 | Q22: 7852.74 | R22: =Q22-P22 -> 1852.74 | S22: 896.41 | T22: 0.5594
B23: 46113 | C23: 205000 | D23: 149974 | E23: =D23-C23 -> -55026 | F23: 35000 | G23: 35924.45 | H23: =G23-F23 -> 924.45 | I23: 240000 | J23: =G23+D23 -> 185898.45 | K23: =J23-I23 -> -54101.55 | L23: -613.52 | M23: =L23/G23 -> -0.017078062 | N23: 2614 | O23: =N23/D23 -> 0.017429688 | P23: 6000 | Q23: 7520.16 | R23: =Q23-P23 -> 1520.16 | S23: 1330.13 | T23: 0.6257
B24: 46143 | C24: 205000 | D24: 181470 | E24: =D24-C24 -> -23530 | F24: 35000 | G24: 41348.88 | H24: =G24-F24 -> 6348.88 | I24: 240000 | J24: =G24+D24 -> 222818.88 | K24: =J24-I24 -> -17181.12 | L24: 3056.22 | M24: =L24/G24 -> 0.073913006 | N24: -4670 | O24: =N24/D24 -> -0.025734281 | P24: 6000 | Q24: 7971.14 | R24: =Q24-P24 -> 1971.14 | S24: -129.83 | T24: 0.4358
B25: 46174 | C25: 205000 | D25: 181309 | E25: =D25-C25 -> -23691 | F25: 35000 | G25: 41046.08 | H25: =G25-F25 -> 6046.08 | I25: 240000 | J25: =G25+D25 -> 222355.08 | K25: =J25-I25 -> -17644.92 | L25: 1420.9 | M25: =L25/G25 -> 0.034617191 | N25: 1715 | O25: =N25/D25 -> 0.0094589899 | P25: 6000 | Q25: 7393.33 | R25: =Q25-P25 -> 1393.33 | S25: 345.82 | T25: 0.4889
B26: 46204 | C26: 205000 | D26: 193208 | E26: =D26-C26 -> -11792 | F26: 35000 | G26: 38787.86 | H26: =G26-F26 -> 3787.86 | I26: 240000 | J26: =G26+D26 -> 231995.86 | K26: =J26-I26 -> -8004.14 | L26: -1824.69 | M26: =L26/G26 -> -0.047042812 | N26: 49 | O26: =N26/D26 -> 0.00025361269 | P26: 6000 | Q26: 8793.95 | R26: =Q26-P26 -> 2793.95 | S26: 2483.05 | T26: 0.7208
B27: 46235 | C27: 205000 | D27: 206841 | E27: =D27-C27 -> 1841 | F27: 35000 | G27: 43875.58 | H27: =G27-F27 -> 8875.58 | I27: 240000 | J27: =G27+D27 -> 250716.58 | K27: =J27-I27 -> 10716.58 | L27: -319.68 | M27: =L27/G27 -> -0.0072860575 | N27: -4298 | O27: =N27/D27 -> -0.020779246 | P27: 6000 | Q27: 9374.82 | R27: =Q27-P27 -> 3374.82 | S27: -778.34 | T27: 0.3559
B28: 46266 | C28: 205000 | E28: =D28-C28 -> -205000 | F28: 35000 | H28: =G28-F28 -> -35000 | I28: 240000 | J28: =G28+D28 -> 0 | K28: =J28-I28 -> -240000 | M28: =L28/G28 -> #DIV/0! | O28: =N28/D28 -> #DIV/0! | P28: 6000 | R28: =Q28-P28 -> -6000
B29: 46296 | C29: 205000 | E29: =D29-C29 -> -205000 | F29: 35000 | H29: =G29-F29 -> -35000 | I29: 240000 | J29: =G29+D29 -> 0 | K29: =J29-I29 -> -240000 | M29: =L29/G29 -> #DIV/0! | O29: =N29/D29 -> #DIV/0! | P29: 6000 | R29: =Q29-P29 -> -6000
B30: 46327 | C30: 205000 | E30: =D30-C30 -> -205000 | F30: 35000 | H30: =G30-F30 -> -35000 | I30: 240000 | J30: =G30+D30 -> 0 | K30: =J30-I30 -> -240000 | M30: =L30/G30 -> #DIV/0! | O30: =N30/D30 -> #DIV/0! | P30: 6000 | R30: =Q30-P30 -> -6000
B31: 46357 | C31: 205000 | E31: =D31-C31 -> -205000 | F31: 35000 | H31: =G31-F31 -> -35000 | I31: 240000 | J31: =G31+D31 -> 0 | K31: =J31-I31 -> -240000 | M31: =L31/G31 -> #DIV/0! | O31: =N31/D31 -> #DIV/0! | P31: 6000 | R31: =Q31-P31 -> -6000
B33: Month | C33: Total Customer # (Fuel, C-Store & Kitchen_ | D33: Crind | E33: DR MOP | F33: Total Crind Debit & Credit | G33: Total Customer # (C-Stores & Kitchen) | H33: Average Customer # (C-Stores & Kitchen) | I33: Average Sales Per Customer (Cstore & Kitchen) | J33: No of Days in a Month | K33: Comments
C34: A | D34: B | E34: C | F34: D=B+C | G34: E=A-D | H34: F=E / H | I34: G=Total Sales/E | J34: H | K34: I
B35: 46023 | C35: 24040 | D35: 4894 | E35: 7154 | F35: =D35+E35 -> 12048 | G35: =C35-F35 -> 11992 | H35: =G35/J35 -> 386.83871 | I35: =J20/G35 -> 13.012137 | J35: 31 | K35: Can delete/Hide this section-just need the two numbers that I put above this
B36: 46054 | C36: 24273 | D36: 4739 | E36: 6990 | F36: =D36+E36 -> 11729 | G36: =C36-F36 -> 12544 | H36: =G36/J36 -> 448 | I36: =J21/G36 -> 12.906304 | J36: 28
B37: 46082 | C37: 28918 | D37: 5910 | E37: 8184 | F37: =D37+E37 -> 14094 | G37: =C37-F37 -> 14824 | H37: =G37/J37 -> 478.19355 | I37: =J22/G37 -> 12.927731 | J37: 31
B38: 46113 | C38: 29105 | D38: 5923 | E38: 8454 | F38: =D38+E38 -> 14377 | G38: =C38-F38 -> 14728 | H38: =G38/J38 -> 490.93333 | I38: =J23/G38 -> 12.622111 | J38: 30
B39: 46143 | C39: 33255 | D39: 6925 | E39: 10012 | F39: =D39+E39 -> 16937 | G39: =C39-F39 -> 16318 | H39: =G39/J39 -> 526.3871 | I39: =J24/G39 -> 13.654791 | J39: 31
B40: 46174 | C40: 31149 | D40: 6182 | E40: 9471 | F40: =D40+E40 -> 15653 | G40: =C40-F40 -> 15496 | H40: =G40/J40 -> 516.53333 | I40: =J25/G40 -> 14.349192 | J40: 30
B41: 46204 | C41: 34234 | D41: 7111 | E41: 10504 | F41: =D41+E41 -> 17615 | G41: =C41-F41 -> 16619 | H41: =G41/J41 -> 536.09677 | I41: =J26/G41 -> 13.959676 | J41: 31
B42: 46235 | C42: 35174 | D42: 7027 | E42: 11015 | F42: =D42+E42 -> 18042 | G42: =C42-F42 -> 17132 | H42: =G42/J42 -> 552.64516 | I42: =J27/G42 -> 14.634402 | J42: 31
B43: 46266 | F43: =D43+E43 -> 0 | G43: =C43-F43 -> 0 | H43: =G43/J43 -> 0 | I43: =J28/G43 -> #DIV/0! | J43: 30
B44: 46296 | F44: =D44+E44 -> 0 | G44: =C44-F44 -> 0 | H44: =G44/J44 -> 0 | I44: =J29/G44 -> #DIV/0! | J44: 31
...

Sheet 0025
B2: Food Variance % and Sales Budget Report Site 0025
B4: Food Margin
B5: Month | C5: GP % Before Discount | D5: Discount % of Sales | E5: Discount $ Total | F5: Target GP % After Discount | G5: Wastage $ | H5: Wastage % | I5: Sampling $ (Free Food) | J5: Sampling % (Free Food) | K5: Spoilage $ | L5: Spoilage % | M5: Logo Cups Adjustment $ | N5: Logo Cups, Adjustment % | O5: T. Target Margin After Adj. % | P5: INIR Net Margin | Q5: Shrink $ | R5: Shrink % | S5: SOS Avg (Average Kitchen Product Time) Mins | T5: Comments
B6: 46023 | C6: 0.6699 | D6: 0.017 | E6: 585 | F6: =C6-D6 -> 0.6529 | G6: 760.14 | H6: =G6/G20 -> 0.036448464 | I6: 0 | J6: =I6/G20 -> 0 | K6: 0 | L6: =K6/G20 -> 0 | M6: 242.99 | N6: =M6/G20 -> 0.011651291 | O6: =F6-H6-J6-L6-N6 -> 0.60480025 | P6: 0.3849 | Q6: =R6*G20 -> -4586.0636 | R6: =P6-O6 -> -0.21990025 | S6: =467.73/60 -> 7.7955
B7: 46054 | C7: 0.6615 | D7: 0.0221 | E7: 1031.23 | F7: =C7-D7 -> 0.6394 | G7: 827.33 | H7: =G7/G21 -> 0.040529028 | I7: 327.92 | J7: =I7/G21 -> 0.01606406 | K7: 0 | L7: =K7/G21 -> 0 | M7: 253.31 | N7: =M7/G21 -> 0.012409085 | O7: =F7-H7-J7-L7-N7 -> 0.57039783 | P7: 0.5494 | Q7: =R7*G21 -> -428.6343 | R7: =P7-O7 -> -0.020997826 | S7: =506.7/60 -> 8.445
B8: 46082 | C8: 0.6624 | D8: 0.0217 | E8: 1075.28 | F8: =C8-D8 -> 0.6407 | G8: 821.69 | H8: =G8/G22 -> 0.034679697 | I8: 514.41 | J8: =I8/G22 -> 0.021710844 | K8: 0 | L8: =K8/G22 -> 0 | M8: 297.87 | N8: =M8/G22 -> 0.012571702 | O8: =F8-H8-J8-L8-N8 -> 0.57173776 | P8: 0.4638 | Q8: =R8*G22 -> -2557.4438 | R8: =P8-O8 -> -0.10793776 | S8: =456.27/60 -> 7.6045
B9: 46113 | C9: 0.6606 | D9: 0.0069 | E9: 631.17 | F9: =C9-D9 -> 0.6537 | G9: 623.91 | H9: =G9/G23 -> 0.026403848 | I9: 429.08 | J9: =I9/G23 -> 0.01815865 | K9: 0 | L9: =K9/G23 -> 0 | M9: 240.62 | N9: =M9/G23 -> 0.01018303 | O9: =F9-H9-J9-L9-N9 -> 0.59895447 | P9: 0.4043 | Q9: =R9*G23 -> -4599.5898 | R9: =P9-O9 -> -0.19465447 | S9: =471.32/60 -> 7.8553333
B10: 46143 | C10: 0.657 | D10: 0.0182 | E10: 808.42 | F10: =C10-D10 -> 0.6388 | G10: 693.7 | H10: =G10/G24 -> 0.028146338 | I10: 379.1 | J10: =I10/G24 -> 0.015381688 | K10: 0 | L10: =K10/I24 -> 0 | M10: 266.04 | N10: =M10/G24 -> 0.010794366 | O10: =F10-H10-J10-L10-N10 -> 0.58447761 | P10: 0.4907 | Q10: =R10*G24 -> -2311.2607 | R10: =P10-O10 -> -0.093777608 | S10: =523.19/60 -> 8.7198333
B11: 46174 | C11: 0.659 | D11: 0.0191 | E11: 751.34 | F11: =C11-D11 -> 0.6399 | G11: 1459.64 | H11: =G11/G25 -> 0.052481438 | I11: 378.46 | J11: =I11/G25 -> 0.013607551 | K11: 0 | L11: =K11/I25 -> 0 | M11: 292.33 | N11: =M11/G25 -> 0.010510742 | O11: =F11-H11-J11-L11-N11 -> 0.56330027 | P11: 0.419 | Q11: =R11*G25 -> -4013.3513 | R11: =P11-O11 -> -0.14430027 | S11: =510.06/60 -> 8.501
B12: 46204 | C12: 0.6591 | D12: 0.0187 | E12: 733.63 | F12: =C12-D12 -> 0.6404 | G12: 1315.24 | H12: =G12/G26 -> 0.050533114 | I12: 453.15 | J12: =I12/G26 -> 0.017410572 | K12: 0 | L12: =K12/I26 -> 0 | M12: 242.2 | N12: =M12/G26 -> 0.0093056173 | O12: =F12-H12-J12-L12-N12 -> 0.5631507 | P12: 0.3999 | Q12: =R12*G26 -> -4248.9732 | R12: =P12-O12 -> -0.1632507 | S12: =509.23/60 -> 8.4871667
B13: 46235 | C13: 0.6644689 | D13: 0.0191047 | E13: 751.31 | F13: =C13-D13 -> 0.6453642 | G13: 1685.55 | H13: =G13/G27 -> 0.064359713 | I13: 817.38 | J13: =I13/G27 -> 0.031210194 | K13: 0 | L13: =K13/I27 -> 0 | M13: 247.52 | N13: =M13/G27 -> 0.0094511087 | O13: =F13-H13-J13-L13-N13 -> 0.54034318 | P13: 0.4824 | Q13: =R13*G27 -> -1517.5042 | R13: =P13-O13 -> -0.057943184 | S13: =540.06/60 -> 9.001
B14: 46266 | F14: =C14-D14 -> 0 | H14: =G14/G28 -> #DIV/0! | J14: =I14/G28 -> #DIV/0! | K14: 0 | L14: =K14/I28 -> 0 | N14: =M14/G28 -> #DIV/0! | O14: =F14-H14-J14-L14-N14 -> #DIV/0! | Q14: =R14*G28 -> #DIV/0! | R14: =P14-O14 -> #DIV/0!
B15: 46296 | F15: =C15-D15 -> 0 | H15: =G15/G29 -> #DIV/0! | J15: =I15/G29 -> #DIV/0! | K15: 0 | L15: =K15/I29 -> 0 | N15: =M15/G29 -> #DIV/0! | O15: =F15-H15-J15-L15-N15 -> #DIV/0! | Q15: =R15*G29 -> #DIV/0! | R15: =P15-O15 -> #DIV/0!
B16: 46327 | F16: =C16-D16 -> 0 | H16: =G16/G30 -> #DIV/0! | J16: =I16/G30 -> #DIV/0! | K16: 0 | L16: =K16/I30 -> 0 | N16: =M16/G30 -> #DIV/0! | O16: =F16-H16-J16-L16-N16 -> #DIV/0! | Q16: =R16*G30 -> #DIV/0! | R16: =P16-O16 -> #DIV/0!
B17: 46357 | F17: =C17-D17 -> 0 | H17: =G17/G31 -> #DIV/0! | J17: =I17/G31 -> #DIV/0! | K17: 0 | L17: =K17/I31 -> 0 | N17: =M17/G31 -> #DIV/0! | O17: =F17-H17-J17-L17-N17 -> #DIV/0! | Q17: =R17*G31 -> #DIV/0! | R17: =P17-O17 -> #DIV/0!
B19: Month | C19: C-Store Retail Sales Budget | D19: C-Store Retail Sales Actual | E19: Variance | F19: Kitchen Sales Budget | G19: Kitchen Sales Actual | H19: Variance | I19: Total Sales Budget | J19: Total Sale (C-Stores & Kitchen) | K19: Variance | L19: Inventory Shrink $ - Kitchen | M19: Inventory Shrink % - Kitchen | N19: Inventory Shrink $ - C-Stores | O19: Inventory Shrink % - C-Stores | P19: Fountain Budget | Q19: Fountain Sales Actual | R19: Fountain Variance | S19: Fountain Inventory Over/Short | T19: Fountain INIR Net Margin
B20: 46023 | C20: 150000 | D20: 76356 | E20: =D20-C20 -> -73644 | F20: 80000 | G20: 20855.2 | H20: =G20-F20 -> -59144.8 | I20: =SUM(F20+C20) -> 230000 | J20: =D20+G20 -> 97211.2 | K20: =J20-I20 -> -132788.8 | L20: -2835.26 | M20: =L20/G20 -> -0.13594979 | N20: 242.99 | O20: =N20/D20 -> 0.0031823301 | P20: 3500 | Q20: 2513.76 | R20: =Q20-P20 -> -986.24 | S20: -569.85 | T20: 0.3183
B21: 46054 | C21: 150000 | D21: 78892 | E21: =D21-C21 -> -71108 | F21: 80000 | G21: 20413.27 | H21: =G21-F21 -> -59586.73 | I21: =SUM(F21+C21) -> 230000 | J21: =D21+G21 -> 99305.27 | K21: =J21-I21 -> -130694.73 | L21: 924.7 | M21: =L21/G21 -> 0.045298965 | N21: 1479 | O21: =N21/D21 -> 0.018747148 | P21: 3500 | Q21: 2484.63 | R21: =Q21-P21 -> -1015.37 | S21: 273.73 | T21: 0.6631
B22: 46082 | C22: 150000 | D22: 88964 | E22: =D22-C22 -> -61036 | F22: 80000 | G22: 23693.69 | H22: =G22-F22 -> -56306.31 | I22: 230000 | J22: =D22+G22 -> 112657.69 | K22: =J22-I22 -> -117342.31 | L22: -1040.49 | M22: =L22/G22 -> -0.043914224 | N22: 2164 | O22: =N22/D22 -> 0.024324446 | P22: 3500 | Q22: 3101.64 | R22: =Q22-P22 -> -398.36 | S22: -131.19 | T22: 0.5018
B23: 46113 | C23: 150000 | D23: 86627 | E23: =D23-C23 -> -63373 | F23: 80000 | G23: 23629.51 | H23: =G23-F23 -> -56370.49 | I23: 230000 | J23: =D23+G23 -> 110256.51 | K23: =J23-I23 -> -119743.49 | L23: -2909.95 | M23: =L23/G23 -> -0.12314898 | N23: -2807 | O23: =N23/D23 -> -0.032403292 | P23: 3500 | Q23: 2861.45 | R23: =Q23-P23 -> -638.55 | S23: -783.02 | T23: 0.2525
B24: 46143 | C24: 150000 | D24: 100074 | E24: =D24-C24 -> -49926 | F24: 80000 | G24: 24646.19 | H24: =G24-F24 -> -55353.81 | I24: 230000 | J24: =D24+G24 -> 124720.19 | K24: =J24-I24 -> -105279.81 | L24: -910.71 | M24: =L24/G24 -> -0.03695135 | N24: -10406 | O24: =N24/D24 -> -0.10398305 | P24: 3500 | Q24: 3657.55 | R24: =Q24-P24 -> 157.55 | S24: -663.57 | T24: 0.3277
B25: 46174 | C25: 150000 | D25: 96422 | E25: =D25-C25 -> -53578 | F25: 80000 | G25: 27812.5 | H25: =G25-F25 -> -52187.5 | I25: 230000 | J25: =D25+G25 -> 124234.5 | K25: =J25-I25 -> -105765.5 | L25: -2454.48 | M25: =L25/G25 -> -0.088250966 | N25: 3422 | O25: =N25/D25 -> 0.035489826 | P25: 3500 | Q25: 3765.06 | R25: =Q25-P25 -> 265.06 | S25: 525.8 | T25: 0.6561
B26: 46204 | C26: 150000 | D26: 96374 | E26: =D26-C26 -> -53626 | F26: 80000 | G26: 26027.29 | H26: =G26-F26 -> -53972.71 | I26: 230000 | J26: =D26+G26 -> 122401.29 | K26: =J26-I26 -> -107598.71 | L26: -2894.53 | M26: =L26/G26 -> -0.11121135 | N26: -4749 | O26: =N26/D26 -> -0.049276776 | P26: 3500 | Q26: 3472.42 | R26: =Q26-P26 -> -27.58 | S26: -808.54 | T26: 0.2718
B27: 46235 | C27: 150000 | D27: 103374 | E27: =D27-C27 -> -46626 | F27: 80000 | G27: 26189.52 | H27: =G27-F27 -> -53810.48 | I27: 230000 | J27: =D27+G27 -> 129563.52 | K27: =J27-I27 -> -100436.48 | L27: -9.54 | M27: =L27/G27 -> -0.00036426784 | N27: 440 | O27: =N27/D27 -> 0.0042563894 | P27: 3500 | Q27: 3787.36 | R27: =Q27-P27 -> 287.36 | S27: -412.25 | T27: 0.3892
B28: 46266 | C28: 150000 | E28: =D28-C28 -> -150000 | F28: 80000 | H28: =G28-F28 -> -80000 | I28: 230000 | J28: =D28+G28 -> 0 | K28: =J28-I28 -> -230000 | M28: =L28/G28 -> #DIV/0! | O28: =N28/D28 -> #DIV/0! | P28: 3500 | R28: =Q28-P28 -> -3500
B29: 46296 | C29: 150000 | E29: =D29-C29 -> -150000 | F29: 80000 | H29: =G29-F29 -> -80000 | I29: 230000 | J29: =D29+G29 -> 0 | K29: =J29-I29 -> -230000 | M29: =L29/G29 -> #DIV/0! | O29: =N29/D29 -> #DIV/0! | P29: 3500 | R29: =Q29-P29 -> -3500
B30: 46327 | C30: 150000 | E30: =D30-C30 -> -150000 | F30: 80000 | H30: =G30-F30 -> -80000 | I30: 230000 | J30: =D30+G30 -> 0 | K30: =J30-I30 -> -230000 | M30: =L30/G30 -> #DIV/0! | O30: =N30/D30 -> #DIV/0! | P30: 3500 | R30: =Q30-P30 -> -3500
B31: 46357 | C31: 150000 | E31: =D31-C31 -> -150000 | F31: 80000 | H31: =G31-F31 -> -80000 | I31: 230000 | J31: =D31+G31 -> 0 | K31: =J31-I31 -> -230000 | M31: =L31/G31 -> #DIV/0! | O31: =N31/D31 -> #DIV/0! | P31: 3500 | R31: =Q31-P31 -> -3500
B33: Month | C33: Total Customer # (Fuel, C-Store & Kitchen_ | D33: Crind | E33: DR MOP | F33: Total Crind Debit & Credit | G33: Total Customer # (C-Stores & Kitchen) | H33: Average Customer # (C-Stores & Kitchen) | I33: Average Sales Per Customer (Cstore & Kitchen) | J33: No of Days in a Month | K33: Comments
C34: A | D34: B | E34: C | F34: D=B+C | G34: E=A-D | H34: F=E / H | I34: G=Total Sales/E | J34: H | K34: I
B35: 46023 | C35: 14020 | D35: 4523 | E35: 8370 | F35: =D35+E35 -> 12893 | G35: =C35-F35 -> 1127 | H35: =G35/J35 -> 36.354839 | I35: =J20/G35 -> 86.25661 | J35: 31 | K35: Can delete/Hide this section-just need the two numbers that I put above this
B36: 46054 | C36: 15561 | D36: 4830 | E36: 9153 | F36: =D36+E36 -> 13983 | G36: =C36-F36 -> 1578 | H36: =G36/J36 -> 56.357143 | I36: =J21/G36 -> 62.931096 | J36: 28
B37: 46082 | C37: 15930 | D37: 5296 | E37: 9373 | F37: =D37+E37 -> 14669 | G37: =C37-F37 -> 1261 | H37: =G37/J37 -> 40.677419 | I37: =J22/G37 -> 89.33996 | J37: 31
B38: 46113 | C38: 17050 | D38: 5513 | E38: 10262 | F38: =D38+E38 -> 15775 | G38: =C38-F38 -> 1275 | H38: =G38/J38 -> 42.5 | I38: =J23/G38 -> 86.475694 | J38: 30
B39: 46143 | C39: 18707 | D39: 5757 | E39: 11007 | F39: =D39+E39 -> 16764 | G39: =C39-F39 -> 1943 | H39: =G39/J39 -> 62.677419 | I39: =J24/G39 -> 64.189496 | J39: 31
B40: 46174 | C40: 18176 | D40: 5187 | E40: 10729 | F40: =D40+E40 -> 15916 | G40: =C40-F40 -> 2260 | H40: =G40/J40 -> 75.333333 | I40: =J25/G40 -> 54.971018 | J40: 30
B41: 46204 | C41: 18627 | D41: 5829 | E41: 11197 | F41: =D41+E41 -> 17026 | G41: =C41-F41 -> 1601 | H41: =G41/J41 -> 51.645161 | I41: =J26/G41 -> 76.453023 | J41: 31
B42: 46235 | C42: 19468 | D42: 5818 | E42: 11503 | F42: =D42+E42 -> 17321 | G42: =C42-F42 -> 2147 | H42: =G42/J42 -> 69.258065 | I42: =J27/G42 -> 60.346306 | J42: 31
B43: 46266 | F43: =D43+E43 -> 0 | G43: =C43-F43 -> 0 | H43: =G43/J43 -> 0 | I43: =J28/G43 -> #DIV/0! | J43: 30
B44: 46296 | F44: =D44+E44 -> 0 | G44: =C44-F44 -> 0 | H44: =G44/J44 -> 0 | I44: =J29/G44 -> #DIV/0! | J44: 31
...

Sheet Sheet1
K1: 31
C2: Total Customer # Fuel, C-Store & Kitchen | D2: Crind | E2: DR MOP | F2: Total Crind Debit & Credit | G2: Total Customer # C-Stores & Kitchen | H2: Average Customer # C-Stores & Kitchen | I2: Total Sale (C-Stores & Kitchen) | J2: Avg Sales Per Customer (Cstore & Kitchen)
C3: A | D3: B | E3: C | F3: D=B+C | G3: E=A-C | H3: F=E/No of days in a month | I3: G=Total Sales | J3: H=G/E
B4: Jan
B5: Feb
B6: Mar
B7: Apr
B8: May
B9: Jun
B10: Jul
B11: Aug
B12: Sep
B13: Oct | C13: 35882 | D13: 4603 | E13: 4372 | F13: =D13+E13 -> 8975 | G13: =C13-F13 -> 26907 | H13: =G13/K1 -> 867.96774 | I13: 163616.49 | J13: =I13/G13 -> 6.080815
B14: Nov | C14: 1041 | D14: 133 | E14: 138 | F14: =D14+E14 -> 271 | G14: =C14-F14 -> 770 | H14: =G14/K1 -> 24.83871 | I14: =103585+16000 -> 119585 | J14: =I14/G14 -> 155.30519
B15: Dec
C17: 77-15 | D17: DPCcridsittot# | E17: DPMOPnetAuthcr#
J19: 670
J20: 138
J21: 362
J22: 262
J23: 560
J24: =SUM(J19:J23) -> 1992
